Workbook

Sheet Brands
A1: ID | B1: Name Tên hãng | C1: Description Mô tả
A2: 1 | B2: Apple | C2: Apple Inc. designs, manufactures and markets smartphones, personal computers, tablets, wearables and accessories, and sells a variety of related services.
A3: 2 | B3: Samsung | C3: Samsung, South Korean company that is one of the world's largest producers of electronic devices.
A4: 3 | B4: JBL | C4: Always leading speaker trends worldwide, JBL Speakers is a famous speaker brand from the United States, making a strong impression worldwide with its unique design, distinctive sound, and combination of many advanced utilities.
A5: 4 | B5: LG | C5: LG Electronics Inc. is a Korean multinational electronics company.

Sheet Categories
A1: ID | B1: Name Tên loại hàng | C1: Description Mô tả
A2: 1 | B2: Watch | C2: Watch, portable timepiece that has a movement driven either by spring or by electricity and that is designed to be worn or carried in the pocket.
A3: 2 | B3: Phone | C3: A mobile phone (or cellphone[a]) is a portable telephone that can make and receive calls over a radio frequency link while the user is moving within a telephone service area, as opposed to a fixed-location phone (landline phone).
A4: 3 | B4: Laptop | C4: A laptop, sometimes called a notebook computer by manufacturers, is a battery- or AC-powered personal computer (PC) smaller than a briefcase.
A5: 4 | B5: Headphone | C5: An equipments to put on your ear to listen music.

Sheet Products
A1: Code | B1: Name Tên sản phẩm | C1: Amount Số lượng *Từ 1 trở lên | D1: Category Loại sản phẩm | F1: Brand Thương hiệu | H1: Buying Prices Giá mua *Tối thiểu 100$ | J1: Selling Prices Giá bán *Tối thiểu 100$ | L1: Storages Tồn kho *Từ 0 trở lên | M1: Link hình (Trong database) | N1: Mã màu | R1: Đã thêm | S1: Tổng số sản phẩm | T1: =COUNTA(A4:A32,A34:A63,A65:A89,A91:A112) -> 101
D2: Tên | E2: Mã (Trong database) | F2: Tên | G2: Mã (Trong database) | N2: R | O2: G | P2: B | Q2: Mã hex
A3: Tai nghe
A4: SGB2P | B4: Samsung Galaxy Buds 2 Pro | C4: 1 | D4: Headphone | E4: =IF(D4 = "","", INDEX(Categories!$A$2:$A$5, MATCH(D4,Categories!$B$2:$B$5, 0))) -> 4 | F4: Samsung | G4: =IF(F4 = "","",INDEX(Brands!$A$2:$A$5, MATCH(F4,Brands!$B$2:$B$5))) -> 2 | H4: 124 | J4: 207 | L4: 944 | M4: /storage/images/Samsung Galaxy Buds 2 Pro.png | N4: 195 | O4: 183 | P4: 211 | Q4: #C3B7D3 | R4: x
A5: SGB2 | B5: Samsung Galaxy Buds 2 | C5: 1 | D5: Headphone | E5: =IF(D5 = "","", INDEX(Categories!$A$2:$A$5, MATCH(D5,Categories!$B$2:$B$5, 0))) -> 4 | F5: Samsung | G5: =IF(F5 = "","",INDEX(Brands!$A$2:$A$5, MATCH(F5,Brands!$B$2:$B$5))) -> 2 | H5: 100 | J5: 124 | L5: 824 | M5: /storage/images/Samsung Galaxy Buds 2.png | N5: 237 | O5: 237 | P5: 237 | Q5: #EDEDED | R5: x
A6: SGBFE | B6: Samsung Galaxy Buds FE | C6: 1 | D6: Headphone | E6: =IF(D6 = "","", INDEX(Categories!$A$2:$A$5, MATCH(D6,Categories!$B$2:$B$5, 0))) -> 4 | F6: Samsung | G6: =IF(F6 = "","",INDEX(Brands!$A$2:$A$5, MATCH(F6,Brands!$B$2:$B$5))) -> 2 | H6: 100 | J6: 110 | L6: 205 | M6: /storage/images/Samsung Galaxy Buds FE.png | N6: 196 | O6: 184 | P6: 213 | Q6: #C4B8D5 | R6: x
E7: =IF(D7 = "","", INDEX(Categories!$A$2:$A$5, MATCH(D7,Categories!$B$2:$B$5, 0))) | G7: =IF(F7 = "","",INDEX(Brands!$A$2:$A$5, MATCH(F7,Brands!$B$2:$B$5)))
A8: AA3M | B8: Apple AirPods 3 MagSafe | C8: 1 | D8: Headphone | E8: =IF(D8 = "","", INDEX(Categories!$A$2:$A$5, MATCH(D8,Categories!$B$2:$B$5, 0))) -> 4 | F8: Apple | G8: =IF(F8 = "","",INDEX(Brands!$A$2:$A$5, MATCH(F8,Brands!$B$2:$B$5))) -> 1 | H8: 165 | J8: 198 | L8: 161 | M8: /storage/images/Apple AirPods 3 MagSafe.png | N8: 228 | O8: 229 | P8: 233 | Q8: #E4E5E9 | R8: x
A9: AA3 | B9: Apple AirPods 3 | C9: 1 | D9: Headphone | E9: =IF(D9 = "","", INDEX(Categories!$A$2:$A$5, MATCH(D9,Categories!$B$2:$B$5, 0))) -> 4 | F9: Apple | G9: =IF(F9 = "","",INDEX(Brands!$A$2:$A$5, MATCH(F9,Brands!$B$2:$B$5))) -> 1 | H9: 165 | J9: 186 | L9: 645 | M9: /storage/images/Apple AirPods 3.png | N9: 228 | O9: 229 | P9: 233 | Q9: #E4E5E9 | R9: x
A10: AAP2USB | B10: Apple AirPods Pro 2 USB-C | C10: 1 | D10: Headphone | E10: =IF(D10 = "","", INDEX(Categories!$A$2:$A$5, MATCH(D10,Categories!$B$2:$B$5, 0))) -> 4 | F10: Apple | G10: =IF(F10 = "","",INDEX(Brands!$A$2:$A$5, MATCH(F10,Brands!$B$2:$B$5))) -> 1 | H10: 227 | J10: 256 | L10: 54 | M10: /storage/images/Apple AirPods Pro 2 USB-C.png | N10: 229 | O10: 231 | P10: 235 | Q10: #E5E7EB | R10: x
A11: AA2 | B11: Apple AirPods 2 | C11: 1 | D11: Headphone | E11: =IF(D11 = "","", INDEX(Categories!$A$2:$A$5, MATCH(D11,Categories!$B$2:$B$5, 0))) -> 4 | F11: Apple | G11: =IF(F11 = "","",INDEX(Brands!$A$2:$A$5, MATCH(F11,Brands!$B$2:$B$5))) -> 1 | H11: 103 | J11: 165 | L11: 849 | M11: /storage/images/Apple AirPods 2.png | N11: 228 | O11: 229 | P11: 233 | Q11: #E4E5E9 | R11: x
A12: AAPM | B12: Apple AirPods Pro Magsafe | C12: 1 | D12: Headphone | E12: =IF(D12 = "","", INDEX(Categories!$A$2:$A$5, MATCH(D12,Categories!$B$2:$B$5, 0))) -> 4 | F12: Apple | G12: =IF(F12 = "","",INDEX(Brands!$A$2:$A$5, MATCH(F12,Brands!$B$2:$B$5))) -> 1 | H12: 165 | J12: 289 | L12: 353 | M12: /storage/images/Apple AirPods Pro Magsafe.png | N12: 230 | O12: 231 | P12: 235 | Q12: #E6E7EB | R12: x
A13: AAP | B13: Apple AirPods Pro 2022 | C13: 1 | D13: Headphone | E13: =IF(D13 = "","", INDEX(Categories!$A$2:$A$5, MATCH(D13,Categories!$B$2:$B$5, 0))) -> 4 | F13: Apple | G13: =IF(F13 = "","",INDEX(Brands!$A$2:$A$5, MATCH(F13,Brands!$B$2:$B$5))) -> 1 | H13: 207 | J13: 256 | L13: 476 | M13: /storage/images/Apple AirPods Pro 2022.png | N13: 231 | O13: 232 | P13: 236 | Q13: #E7E8EC | R13: x
E14: =IF(D14 = "","", INDEX(Categories!$A$2:$A$5, MATCH(D14,Categories!$B$2:$B$5, 0))) | G14: =IF(F14 = "","",INDEX(Brands!$A$2:$A$5, MATCH(F14,Brands!$B$2:$B$5)))
A15: JTF | B15: JBL Tune Flex | C15: 1 | D15: Headphone | E15: =IF(D15 = "","", INDEX(Categories!$A$2:$A$5, MATCH(D15,Categories!$B$2:$B$5, 0))) -> 4 | F15: JBL | G15: =IF(F15 = "","",INDEX(Brands!$A$2:$A$5, MATCH(F15,Brands!$B$2:$B$5))) -> 1 | H15: 100 | J15: 111 | L15: 97 | M15: /storage/images/JBL Tune Flex.png | N15: 51 | O15: 77 | P15: 104 | Q15: #334D68 | R15: x
A16: JT230TWS | B16: JBL Tune 230 TWS | C16: 1 | D16: Headphone | E16: =IF(D16 = "","", INDEX(Categories!$A$2:$A$5, MATCH(D16,Categories!$B$2:$B$5, 0))) -> 4 | F16: JBL | G16: =IF(F16 = "","",INDEX(Brands!$A$2:$A$5, MATCH(F16,Brands!$B$2:$B$5))) -> 1 | H16: 100 | J16: 102 | L16: 504 | M16: /storage/images/JBL Tune 230 TWS.png | N16: 220 | O16: 218 | P16: 219 | Q16: #DCDADB | R16: x
A17: JTB | B17: JBL Tune Beam | C17: 1 | D17: Headphone | E17: =IF(D17 = "","", INDEX(Categories!$A$2:$A$5, MATCH(D17,Categories!$B$2:$B$5, 0))) -> 4 | F17: JBL | G17: =IF(F17 = "","",INDEX(Brands!$A$2:$A$5, MATCH(F17,Brands!$B$2:$B$5))) -> 1 | H17: 100 | J17: 102 | L17: 838 | M17: /storage/images/JBL Tune Beam.png | N17: 153 | O17: 149 | P17: 190 | Q17: #9995BE | R17: x
A18: JWB | B18: JBL Wave Beam | C18: 1 | D18: Headphone | E18: =IF(D18 = "","", INDEX(Categories!$A$2:$A$5, MATCH(D18,Categories!$B$2:$B$5, 0))) -> 4 | F18: JBL | G18: =IF(F18 = "","",INDEX(Brands!$A$2:$A$5, MATCH(F18,Brands!$B$2:$B$5))) -> 1 | H18: 100 | I18: 60 | J18: 101 | K18: 62 | L18: 382 | M18: /storage/images/JBL Wave Beam.png | N18: 204 | O18: 175 | P18: 145 | Q18: #CCAF91 | R18: x
A19: JT120TWS | B19: JBL Tune 120 TWS | C19: 1 | D19: Headphone | E19: =IF(D19 = "","", INDEX(Categories!$A$2:$A$5, MATCH(D19,Categories!$B$2:$B$5, 0))) -> 4 | F19: JBL | G19: =IF(F19 = "","",INDEX(Brands!$A$2:$A$5, MATCH(F19,Brands!$B$2:$B$5))) -> 1 | H19: 100 | I19: 83 | J19: 101 | K19: 98 | L19: 321 | M19: /storage/images/JBL Tune 120 TWS.png | N19: 36 | O19: 36 | P19: 34 | Q19: #242222 | R19: x
A20: JT115TWS | B20: JBL Tune 115 TWS | C20: 1 | D20: Headphone | E20: =IF(D20 = "","", INDEX(Categories!$A$2:$A$5, MATCH(D20,Categories!$B$2:$B$5, 0))) -> 4 | F20: JBL | G20: =IF(F20 = "","",INDEX(Brands!$A$2:$A$5, MATCH(F20,Brands!$B$2:$B$5))) -> 1 | H20: 100 | I20: 20 | J20: 101 | K20: 61 | L20: 554 | M20: /storage/images/JBL Tune 115 TWS.png | N20: 61 | O20: 61 | P20: 63 | Q20: #3D3D3F | R20: x
A21: JLP2 | B21: JBL Live Pro 2 | C21: 1 | D21: Headphone | E21: =IF(D21 = "","", INDEX(Categories!$A$2:$A$5, MATCH(D21,Categories!$B$2:$B$5, 0))) -> 4 | F21: JBL | G21: =IF(F21 = "","",INDEX(Brands!$A$2:$A$5, MATCH(F21,Brands!$B$2:$B$5))) -> 1 | H21: 103 | J21: 165 | L21: 840 | M21: /storage/images/JBL Live Pro 2.png | N21: 108 | O21: 122 | P21: 161 | Q21: #6C7AA1 | R21: x
A22: JTP2 | B22: JBL Tour Pro 2 | C22: 1 | D22: Headphone | E22: =IF(D22 = "","", INDEX(Categories!$A$2:$A$5, MATCH(D22,Categories!$B$2:$B$5, 0))) -> 4 | F22: JBL | G22: =IF(F22 = "","",INDEX(Brands!$A$2:$A$5, MATCH(F22,Brands!$B$2:$B$5))) -> 1 | H22: 185 | J22: 247 | L22: 818 | M22: /storage/images/JBL Tour Pro 2.png | N22: 46 | O22: 46 | P22: 46 | Q22: #2E2E2E | R22: x
A23: JLP | B23: JBL Live Pro+ | C23: 1 | D23: Headphone | E23: =IF(D23 = "","", INDEX(Categories!$A$2:$A$5, MATCH(D23,Categories!$B$2:$B$5, 0))) -> 4 | F23: JBL | G23: =IF(F23 = "","",INDEX(Brands!$A$2:$A$5, MATCH(F23,Brands!$B$2:$B$5))) -> 1 | H23: 100 | I23: 83 | J23: 124 | L23: 29 | M23: /storage/images/JBL Live Pro+.png | N23: 220 | O23: 186 | P23: 187 | Q23: #DCBABB | R23: x
A24: JCP | B24: JBL Club Pro+ | C24: 1 | D24: Headphone | E24: =IF(D24 = "","", INDEX(Categories!$A$2:$A$5, MATCH(D24,Categories!$B$2:$B$5, 0))) -> 4 | F24: JBL | G24: =IF(F24 = "","",INDEX(Brands!$A$2:$A$5, MATCH(F24,Brands!$B$2:$B$5))) -> 1 | H24: 144 | J24: 206 | L24: 16 | M24: /storage/images/JBL Club Pro+.png | N24: 36 | O24: 36 | P24: 36 | Q24: #242424 | R24: x
A25: JT770NC | B25: JBL Tune 770NC | C25: 1 | D25: Headphone | E25: =IF(D25 = "","", INDEX(Categories!$A$2:$A$5, MATCH(D25,Categories!$B$2:$B$5, 0))) -> 4 | F25: JBL | G25: =IF(F25 = "","",INDEX(Brands!$A$2:$A$5, MATCH(F25,Brands!$B$2:$B$5))) -> 1 | H25: 124 | J25: 144 | L25: 722 | M25: /storage/images/JBL Tune 770NC.png | N25: 73 | O25: 84 | P25: 109 | Q25: #49546D | R25: x
A26: JT670NC | B26: JBL Tune 670NC | C26: 1 | D26: Headphone | E26: =IF(D26 = "","", INDEX(Categories!$A$2:$A$5, MATCH(D26,Categories!$B$2:$B$5, 0))) -> 4 | F26: JBL | G26: =IF(F26 = "","",INDEX(Brands!$A$2:$A$5, MATCH(F26,Brands!$B$2:$B$5))) -> 1 | H26: 100 | J26: 102 | L26: 782 | M26: /storage/images/JBL Tune 670NC.png | N26: 154 | O26: 146 | P26: 187 | Q26: #9A92BB | R26: x
A27: JL670NC | B27: JBL Live 670NC | C27: 1 | D27: Headphone | E27: =IF(D27 = "","", INDEX(Categories!$A$2:$A$5, MATCH(D27,Categories!$B$2:$B$5, 0))) -> 4 | F27: JBL | G27: =IF(F27 = "","",INDEX(Brands!$A$2:$A$5, MATCH(F27,Brands!$B$2:$B$5))) -> 1 | H27: 103 | J27: 124 | L27: 51 | M27: /storage/images/JBL Live 670NC.png | N27: 32 | O27: 32 | P27: 32 | Q27: #202020 | R27: x
A28: JT520BT | B28: JBL Tune 520BT | C28: 1 | D28: Headphone | E28: =IF(D28 = "","", INDEX(Categories!$A$2:$A$5, MATCH(D28,Categories!$B$2:$B$5, 0))) -> 4 | F28: JBL | G28: =IF(F28 = "","",INDEX(Brands!$A$2:$A$5, MATCH(F28,Brands!$B$2:$B$5))) -> 1 | H28: 100 | I28: 50 | J28: 101 | K28: 58 | L28: 737 | M28: /storage/images/JBL Tune 520BT.png | N28: 232 | O28: 232 | P28: 232 | Q28: #E8E8E8 | R28: x
A29: JT510BT | B29: JBL Tune 510BT | C29: 1 | D29: Headphone | E29: =IF(D29 = "","", INDEX(Categories!$A$2:$A$5, MATCH(D29,Categories!$B$2:$B$5, 0))) -> 4 | F29: JBL | G29: =IF(F29 = "","",INDEX(Brands!$A$2:$A$5, MATCH(F29,Brands!$B$2:$B$5))) -> 1 | H29: 100 | I29: 41 | J29: 101 | K29: 58 | L29: 633 | M29: /storage/images/JBL Tune 510BT.png | N29: 203 | O29: 190 | P29: 197 | Q29: #CBBEC5 | R29: x
A30: JT500 | B30: JBL Tune 500 | C30: 1 | D30: Headphone | E30: =IF(D30 = "","", INDEX(Categories!$A$2:$A$5, MATCH(D30,Categories!$B$2:$B$5, 0))) -> 4 | F30: JBL | G30: =IF(F30 = "","",INDEX(Brands!$A$2:$A$5, MATCH(F30,Brands!$B$2:$B$5))) -> 1 | H30: 100 | I30: 20 | J30: 101 | K30: 37 | L30: 932 | M30: /storage/images/JBL Tune 500.png | N30: 51 | O30: 51 | P30: 51 | Q30: #333333 | R30: x
A31: JQO | B31: JBL Quantum One | C31: 1 | D31: Headphone | E31: =IF(D31 = "","", INDEX(Categories!$A$2:$A$5, MATCH(D31,Categories!$B$2:$B$5, 0))) -> 4 | F31: JBL | G31: =IF(F31 = "","",INDEX(Brands!$A$2:$A$5, MATCH(F31,Brands!$B$2:$B$5))) -> 1 | H31: 100 | I31: 82 | J31: 226 | L31: 144 | M31: /storage/images/JBL Quantum One.png | N31: 105 | O31: 105 | P31: 105 | Q31: #696969 | R31: x
A32: JQ400 | B32: JBL Quantum 400 | C32: 1 | D32: Headphone | E32: =IF(D32 = "","", INDEX(Categories!$A$2:$A$5, MATCH(D32,Categories!$B$2:$B$5, 0))) -> 4 | F32: JBL | G32: =IF(F32 = "","",INDEX(Brands!$A$2:$A$5, MATCH(F32,Brands!$B$2:$B$5))) -> 1 | H32: 100 | J32: 102 | L32: 657 | M32: /storage/images/JBL Quantum 400.png | N32: 77 | O32: 78 | P32: 80 | Q32: #4D4E50 | R32: x
A33: Điện thoại
A34: IP15PM | B34: iPhone 15 Pro Max | C34: 1 | D34: Phone | E34: =IF(D34 = "","", INDEX(Categories!$A$2:$A$5, MATCH(D34,Categories!$B$2:$B$5, 0))) -> 2 | F34: Apple | G34: =IF(F34 = "","",INDEX(Brands!$A$2:$A$5, MATCH(F34,Brands!$B$2:$B$5))) -> 1 | H34: 2200 | J34: 2500 | L34: 512 | M34: /storage/images/iPhone 15 Pro Max.png | N34: 150 | O34: 146 | P34: 141 | Q34: #96928D | R34: x
A35: IP15P | B35: iPhone 15 Pro | C35: 1 | D35: Phone | E35: =IF(D35 = "","", INDEX(Categories!$A$2:$A$5, MATCH(D35,Categories!$B$2:$B$5, 0))) -> 2 | F35: Apple | G35: =IF(F35 = "","",INDEX(Brands!$A$2:$A$5, MATCH(F35,Brands!$B$2:$B$5))) -> 1 | H35: 1072 | J35: 1196 | L35: 264 | M35: /storage/images/iPhone 15 Pro.png | N35: 72 | O35: 77 | P35: 82 | Q35: #484D52 | R35: x
A36: IP15PL | B36: iPhone 15 Plus | C36: 1 | D36: Phone | E36: =IF(D36 = "","", INDEX(Categories!$A$2:$A$5, MATCH(D36,Categories!$B$2:$B$5, 0))) -> 2 | F36: Apple | G36: =IF(F36 = "","",INDEX(Brands!$A$2:$A$5, MATCH(F36,Brands!$B$2:$B$5))) -> 1 | H36: 948 | J36: 1072 | L36: 713 | M36: /storage/images/iPhone 15 Plus.png | N36: 254 | O36: 228 | P36: 227 | Q36: #FEE4E3 | R36: x
A37: IP15 | B37: iPhone 15 | C37: 1 | D37: Phone | E37: =IF(D37 = "","", INDEX(Categories!$A$2:$A$5, MATCH(D37,Categories!$B$2:$B$5, 0))) -> 2 | F37: Apple | G37: =IF(F37 = "","",INDEX(Brands!$A$2:$A$5, MATCH(F37,Brands!$B$2:$B$5))) -> 1 | H37: 825 | J37: 948 | L37: 942 | M37: /storage/images/iPhone 15.png | N37: 254 | O37: 249 | P37: 227 | Q37: #FEF9E3 | R37: x
A38: IP14PM | B38: iPhone 14 Pro Max | C38: 1 | D38: Phone | E38: =IF(D38 = "","", INDEX(Categories!$A$2:$A$5, MATCH(D38,Categories!$B$2:$B$5, 0))) -> 2 | F38: Apple | G38: =IF(F38 = "","",INDEX(Brands!$A$2:$A$5, MATCH(F38,Brands!$B$2:$B$5))) -> 1 | H38: 1031 | J38: 1237 | L38: 791 | M38: /storage/images/iPhone 14 Pro Max.png | N38: 65 | O38: 59 | P38: 71 | Q38: #413B47 | R38: x
A39: IP14P | B39: iPhone 14 Pro | C39: 1 | D39: Phone | E39: =IF(D39 = "","", INDEX(Categories!$A$2:$A$5, MATCH(D39,Categories!$B$2:$B$5, 0))) -> 2 | F39: Apple | G39: =IF(F39 = "","",INDEX(Brands!$A$2:$A$5, MATCH(F39,Brands!$B$2:$B$5))) -> 1 | H39: 947 | J39: 1155 | L39: 35 | M39: /storage/images/iPhone 14 Pro.png | N39: 65 | O39: 59 | P39: 71 | Q39: #413B47 | R39: x
A40: IP14PL | B40: iPhone 14 Plus | C40: 1 | D40: Phone | E40: =IF(D40 = "","", INDEX(Categories!$A$2:$A$5, MATCH(D40,Categories!$B$2:$B$5, 0))) -> 2 | F40: Apple | G40: =IF(F40 = "","",INDEX(Brands!$A$2:$A$5, MATCH(F40,Brands!$B$2:$B$5))) -> 1 | H40: 784 | J40: 1031 | L40: 787 | M40: /storage/images/iPhone 14 Plus.png | N40: 157 | O40: 174 | P40: 192 | Q40: #9DAEC0 | R40: x
...

Sheet Sale
A1: Name Tên khuyến mãi | B1: Name Mã khuyến mãi | C1: Price Giá tiền giảm | D1: Rank Hạng thành viên được áp dụng | E1: Amount Số lượng | F1: Date Start Ngày bắt đầu | G1: Date End Ngày kết thúc
A2: Sale 10 | B2: SALE10 | C2: 10 | D2: Đồng | E2: 100 | F2: 2023-12-31 | G2: 2050-12-31
A3: Sale 10000000 | B3: SALEOVERPRICE | C3: 10000000 | D3: Đồng | E3: 200 | F3: 2023-12-31 | G3: 2050-12-31
A4: Sale Expired | B4: SALEEXPIRED | C4: 100 | D4: Đồng | E4: 200 | F4: 2023-11-01 | G4: 2023-12-01
A5: Out Of Sale | B5: OUTOFSALE | C5: 100 | D5: Đồng | E5: 0 | F5: 2023-11-01 | G5: 2050-12-31

Sheet Rank
A1: Name Tên hạng thành viên | B1: Discount % Tỷ lệ giảm giá | C1: Value Số tiền cần đạt ? | D1: Description Mô tả
A2: Đồng | B2: 5 | C2: 10000 | D2: Cho người mới vào

Sheet Bank Account
A1: Ngân hàng | B1: Số thẻ | C1: Tên chủ thẻ | D1: Ngày phát hành | E1: OTP | F1: Ghi chú | G1: Thông báo trên hệ thống
A2: NCB | B2: 9704198526191432198 | C2: NGUYEN VAN A | D2: 07/15 | E2: 123456 | F2: Thành công
A3: NCB | B3: 9704195798459170488 | C3: NGUYEN VAN A | D3: 07/15 | F3: Thẻ không đủ số dư | G3: Your account does not have enough balance for the transaction
A4: NCB | B4: 9704192181368742 | C4: NGUYEN VAN A | D4: 07/15 | F4: Thẻ chưa kích hoạt | G4: Your card hasn’t been active
A5: NCB | B5: 9704193370791314 | C5: NGUYEN VAN A | D5: 07/15 | F5: Thẻ bị khóa | G5: Card locked
A6: NCB | B6: 9704194841945513 | C6: NGUYEN VAN A | D6: 07/15 | F6: Thẻ bị hết hạn | G6: Card expires
